ðŸ–‡ AgentOps: [34mSession Replay: https://app.agentops.ai/drilldown?session_id=3ab49a1f-b300-444b-bf31-20d003186f71[0m
ðŸ–‡ AgentOps: Cannot start session - session already started
ðŸ–‡ AgentOps: This run's cost $0.00
ðŸ–‡ AgentOps: [34mSession Replay: https://app.agentops.ai/drilldown?session_id=3ab49a1f-b300-444b-bf31-20d003186f71[0m
Traceback (most recent call last):
  File "<string>", line 1, in <module>
RuntimeError: Dora Runtime raised an error.

Caused by:
   0: main task failed
   1: operator agents/op raised an error
   2: error in Python module at /mnt/d/project/zzbc/experiment_project/experiment_project/moxin/agent/reasoning_agent.py
   3: Traceback (most recent call last):
        File "/mnt/d/project/zzbc/experiment_project/experiment_project/moxin/agent/reasoning_agent.py", line 58, in on_event
          result = reasoning.forward(question=task).answer
                   ^^^^^^^^^^^^^^^^^^^^^^^^^^^^^^^^
        File "/mnt/d/project/zzbc/experiment_project/experiment_project/moxin/agent/reasoning_agent.py", line 23, in forward
          return self.prog(question=question)
                 ^^^^^^^^^^^^^^^^^^^^^^^^^^^^
        File "/home/cc/miniconda/lib/python3.12/site-packages/dspy/predict/predict.py", line 61, in __call__
          return self.forward(**kwargs)
                 ^^^^^^^^^^^^^^^^^^^^^^
        File "/home/cc/miniconda/lib/python3.12/site-packages/dspy/predict/predict.py", line 103, in forward
          x, C = dsp.generate(template, **config)(x, stage=self.stage)
                 ^^^^^^^^^^^^^^^^^^^^^^^^^^^^^^^^^^^^^^^^^^^^^^^^^^^^^
        File "/home/cc/miniconda/lib/python3.12/site-packages/dsp/primitives/predict.py", line 77, in do_generate
          completions: list[dict[str, Any]] = generator(prompt, **kwargs)
                                              ^^^^^^^^^^^^^^^^^^^^^^^^^^^
        File "/home/cc/miniconda/lib/python3.12/site-packages/dsp/modules/gpt3.py", line 178, in __call__
          response = self.request(prompt, **kwargs)
                     ^^^^^^^^^^^^^^^^^^^^^^^^^^^^^^
        File "/home/cc/miniconda/lib/python3.12/site-packages/backoff/_sync.py", line 105, in retry
          ret = target(*args, **kwargs)
                ^^^^^^^^^^^^^^^^^^^^^^^
        File "/home/cc/miniconda/lib/python3.12/site-packages/dsp/modules/gpt3.py", line 144, in request
          return self.basic_request(prompt, **kwargs)
                 ^^^^^^^^^^^^^^^^^^^^^^^^^^^^^^^^^^^^
        File "/home/cc/miniconda/lib/python3.12/site-packages/dsp/modules/gpt3.py", line 121, in basic_request
          response = completions_request(**kwargs)
                     ^^^^^^^^^^^^^^^^^^^^^^^^^^^^^
        File "/home/cc/miniconda/lib/python3.12/site-packages/dsp/modules/gpt3.py", line 270, in completions_request
          return v1_cached_gpt3_request_v2_wrapped(**kwargs).model_dump()
                 ^^^^^^^^^^^^^^^^^^^^^^^^^^^^^^^^^^^^^^^^^^^
        File "/home/cc/miniconda/lib/python3.12/site-packages/dsp/modules/cache_utils.py", line 16, in wrapper
          return func(*args, **kwargs)
                 ^^^^^^^^^^^^^^^^^^^^^
        File "/home/cc/miniconda/lib/python3.12/site-packages/dsp/modules/gpt3.py", line 243, in v1_cached_gpt3_request_v2_wrapped
          return v1_cached_gpt3_request_v2(**kwargs)
                 ^^^^^^^^^^^^^^^^^^^^^^^^^^^^^^^^^^^
        File "/home/cc/miniconda/lib/python3.12/site-packages/joblib/memory.py", line 655, in __call__
          return self._cached_call(args, kwargs)[0]
                 ^^^^^^^^^^^^^^^^^^^^^^^^^^^^^^^
        File "/home/cc/miniconda/lib/python3.12/site-packages/joblib/memory.py", line 598, in _cached_call
          out, metadata = self.call(*args, **kwargs)
                          ^^^^^^^^^^^^^^^^^^^^^^^^^^
        File "/home/cc/miniconda/lib/python3.12/site-packages/joblib/memory.py", line 856, in call
          output = self.func(*args, **kwargs)
                   ^^^^^^^^^^^^^^^^^^^^^^^^^^
        File "/home/cc/miniconda/lib/python3.12/site-packages/dsp/modules/gpt3.py", line 237, in v1_cached_gpt3_request_v2
          return openai.completions.create(**kwargs)
                 ^^^^^^^^^^^^^^^^^^^^^^^^^^^^^^^^^^^
        File "/home/cc/miniconda/lib/python3.12/site-packages/openai/_utils/_utils.py", line 275, in wrapper
          return func(*args, **kwargs)
                 ^^^^^^^^^^^^^^^^^^^^^
        File "/home/cc/miniconda/lib/python3.12/site-packages/openai/resources/completions.py", line 516, in create
          return self._post(
                 ^^^^^^^^^^^
        File "/home/cc/miniconda/lib/python3.12/site-packages/openai/_base_client.py", line 1213, in post
          return cast(ResponseT, self.request(cast_to, opts, stream=stream, stream_cls=stream_cls))
                                 ^^^^^^^^^^^^^^^^^^^^^^^^^^^^^^^^^^^^^^^^^^^^^^^^^^^^^^^^^^^^^^^^^
        File "/home/cc/miniconda/lib/python3.12/site-packages/openai/_base_client.py", line 902, in request
          return self._request(
                 ^^^^^^^^^^^^^^
        File "/home/cc/miniconda/lib/python3.12/site-packages/openai/_base_client.py", line 993, in _request
          raise self._make_status_error_from_response(err.response) from None

      NotFoundError: Error code: 404

Location:
    binaries/runtime/src/operator/python.rs:28:9
